#usda 1.0
(
    customLayerData = {
        string creator = "URDF USD Converter v0.1.0"
    }
    defaultPrim = "robotiq_gripper"
    doc = """Generated from Composed Stage of root layer /tmp/tmp0ieqjgvi/robotiq_gripper.usdc


Generated from Composed Stage of root layer /workspace/robots/robotiq_2f_85/usd/usdex/robotiq_gripper.usdc


Generated from Composed Stage of root layer /workspace/robots/robotiq_2f_85/usd/temp/robotiq_2f_85.usd


Generated from Composed Stage of root layer /workspace/robots/robotiq_2f_85/usd/robotiq_2f_85/payloads/base.usd
"""
    kilogramsPerUnit = 1
    metersPerUnit = 1
    upAxis = "Z"
)

over "robotiq_gripper"
{
    over "Geometry"
    {
        over "world"
        {
            over "robotiq_85_base_link" (
                prepend apiSchemas = ["PhysicsRigidBodyAPI", "PhysicsArticulationRootAPI", "NewtonArticulationRootAPI", "PhysicsMassAPI"]
            )
            {
                bool newton:selfCollisionEnabled = 0
                point3f physics:centerOfMass = (0, 0.00002274, 0.03232288)
                float3 physics:diagonalInertia = (0.00039462722, 0.00051617814, 0.00058802264)
                float physics:mass = 0.663202
                quatf physics:principalAxes = (0.49947998, 0.5005193, 0.5003153, 0.4996847)

                over "robotiq_85_left_knuckle_link" (
                    prepend apiSchemas = ["PhysicsRigidBodyAPI", "PhysicsMassAPI"]
                )
                {
                    point3f physics:centerOfMass = (0.01213197, 0.0002, -0.00058647)
                    float3 physics:diagonalInertia = (3.4500846e-7, 0.0000022386716, 0.00000231944)
                    float physics:mass = 0.013847732
                    quatf physics:principalAxes = (-0.7067651, 0.7067651, 0.021979524, -0.021979524)

                    over "robotiq_85_left_finger_link" (
                        prepend apiSchemas = ["PhysicsRigidBodyAPI", "PhysicsMassAPI"]
                    )
                    {
                        point3f physics:centerOfMass = (0.00346899, -0.00079447, 0.01867121)
                        float3 physics:diagonalInertia = (0.000004682275, 0.00001183208, 0.000014372365)
                        float physics:mass = 0.04260377
                        quatf physics:principalAxes = (0.78435075, 1.7693344e-17, 0.6203176, -1.3536424e-16)

                        over "robotiq_85_left_finger_tip_link" (
                            prepend apiSchemas = ["PhysicsRigidBodyAPI", "PhysicsMassAPI"]
                        )
                        {
                            point3f physics:centerOfMass = (-0.01456706, -0.0008, 0.01649701)
                            float3 physics:diagonalInertia = (0.0000026440466, 0.00001197888, 0.000012065313)
                            float physics:mass = 0.04268589
                            quatf physics:principalAxes = (0.54313433, 0, 0.8396458, 0)
                        }
                    }
                }

                over "robotiq_85_right_knuckle_link" (
                    prepend apiSchemas = ["PhysicsRigidBodyAPI", "PhysicsMassAPI"]
                )
                {
                    point3f physics:centerOfMass = (-0.01213197, 0.0002, -0.00058647)
                    float3 physics:diagonalInertia = (3.4500846e-7, 0.0000022386716, 0.00000231944)
                    float physics:mass = 0.013847732
                    quatf physics:principalAxes = (0.7067651, -0.7067651, 0.021979524, -0.021979524)

                    over "robotiq_85_right_finger_link" (
                        prepend apiSchemas = ["PhysicsRigidBodyAPI", "PhysicsMassAPI"]
                    )
                    {
                        point3f physics:centerOfMass = (-0.00346899, -0.00000553, 0.01867121)
                        float3 physics:diagonalInertia = (0.000004682275, 0.00001183208, 0.000014372365)
                        float physics:mass = 0.04260377
                        quatf physics:principalAxes = (0.6203176, -1.3536424e-16, 0.78435075, 1.7693344e-17)

                        over "robotiq_85_right_finger_tip_link" (
                            prepend apiSchemas = ["PhysicsRigidBodyAPI", "PhysicsMassAPI"]
                        )
                        {
                            point3f physics:centerOfMass = (0.01456706, 0.00005, 0.01649701)
                            float3 physics:diagonalInertia = (0.0000026440466, 0.00001197888, 0.000012065313)
                            float physics:mass = 0.04268589
                            quatf physics:principalAxes = (0.8396458, 0, 0.54313433, 0)
                        }
                    }
                }

                over "robotiq_85_left_inner_knuckle_link" (
                    prepend apiSchemas = ["PhysicsRigidBodyAPI", "PhysicsMassAPI"]
                )
                {
                    point3f physics:centerOfMass = (0.01897699, 0.00015001, 0.02247101)
                    float3 physics:diagonalInertia = (0.000004887118, 0.00000869056, 0.000012875682)
                    float physics:mass = 0.029693764
                    quatf physics:principalAxes = (0.9064055, 3.0621588e-17, 0.4224086, 2.0734926e-16)
                }

                over "robotiq_85_right_inner_knuckle_link" (
                    prepend apiSchemas = ["PhysicsRigidBodyAPI", "PhysicsMassAPI"]
                )
                {
                    point3f physics:centerOfMass = (-0.01926824, 0.00005001, 0.02222178)
                    float3 physics:diagonalInertia = (0.0000048807565, 0.00000869056, 0.000012882044)
                    float physics:mass = 0.029693764
                    quatf physics:principalAxes = (0.41391107, -2.0694741e-16, 0.9103173, -6.098e-17)
                }
            }
        }
    }

    over "Physics"
    {
        def PhysicsRevoluteJoint "robotiq_85_left_knuckle_joint" (
            prepend apiSchemas = ["PhysicsDriveAPI:angular", "PhysicsJointStateAPI:angular"]
        )
        {
            float drive:angular:physics:maxForce = 50
            uniform token physics:axis = "Y"
            custom rel physics:body0
            prepend rel physics:body0 = </robotiq_gripper>
            custom rel physics:body1
            prepend rel physics:body1 = </robotiq_gripper/Geometry/world/robotiq_85_base_link/robotiq_85_left_knuckle_link>
            point3f physics:localPos0 = (0.03060114, 0, 0.05490452)
            point3f physics:localPos1 = (0, 0, 0)
            quatf physics:localRot0 = (0, -1, 0, 0)
            quatf physics:localRot1 = (0, -1, 0, 0)
            float physics:lowerLimit = 0
            float physics:upperLimit = 45.836624
            custom float urdf:limit:effort = 50
            custom float urdf:limit:velocity = 0.5
        }

        def PhysicsRevoluteJoint "robotiq_85_right_knuckle_joint" (
            prepend apiSchemas = ["NewtonMimicAPI", "PhysicsDriveAPI:angular", "PhysicsJointStateAPI:angular"]
        )
        {
            float drive:angular:physics:maxForce = 50
            float newton:mimicCoef1 = -1
            rel newton:mimicJoint = </robotiq_gripper/Physics/robotiq_85_left_knuckle_joint>
            uniform token physics:axis = "Y"
            custom rel physics:body0
            prepend rel physics:body0 = </robotiq_gripper>
            custom rel physics:body1
            prepend rel physics:body1 = </robotiq_gripper/Geometry/world/robotiq_85_base_link/robotiq_85_right_knuckle_link>
            point3f physics:localPos0 = (-0.03060114, 0, 0.05490452)
            point3f physics:localPos1 = (0, 0, 0)
            quatf physics:localRot0 = (0, -1, 0, 0)
            quatf physics:localRot1 = (0, -1, 0, 0)
            float physics:lowerLimit = -45.836624
            float physics:upperLimit = 0
            custom float urdf:limit:effort = 50
            custom float urdf:limit:velocity = 0.5
        }

        def PhysicsRevoluteJoint "robotiq_85_left_inner_knuckle_joint" (
            prepend apiSchemas = ["NewtonMimicAPI", "PhysicsDriveAPI:angular", "PhysicsJointStateAPI:angular"]
        )
        {
            rel newton:mimicJoint = </robotiq_gripper/Physics/robotiq_85_left_knuckle_joint>
            uniform token physics:axis = "Y"
            custom rel physics:body0
            prepend rel physics:body0 = </robotiq_gripper>
            custom rel physics:body1
            prepend rel physics:body1 = </robotiq_gripper/Geometry/world/robotiq_85_base_link/robotiq_85_left_inner_knuckle_link>
            point3f physics:localPos0 = (0.0127, 0, 0.06142)
            point3f physics:localPos1 = (0, 0, 0)
            quatf physics:localRot0 = (0, -1, 0, 0)
            quatf physics:localRot1 = (0, -1, 0, 0)
        }

        def PhysicsRevoluteJoint "robotiq_85_right_inner_knuckle_joint" (
            prepend apiSchemas = ["NewtonMimicAPI", "PhysicsDriveAPI:angular", "PhysicsJointStateAPI:angular"]
        )
        {
            float newton:mimicCoef1 = -1
            rel newton:mimicJoint = </robotiq_gripper/Physics/robotiq_85_left_knuckle_joint>
            uniform token physics:axis = "Y"
            custom rel physics:body0
            prepend rel physics:body0 = </robotiq_gripper>
            custom rel physics:body1
            prepend rel physics:body1 = </robotiq_gripper/Geometry/world/robotiq_85_base_link/robotiq_85_right_inner_knuckle_link>
            point3f physics:localPos0 = (-0.0127, 0, 0.06142)
            point3f physics:localPos1 = (0, 0, 0)
            quatf physics:localRot0 = (0, -1, 0, 0)
            quatf physics:localRot1 = (0, -1, 0, 0)
        }

        def PhysicsRevoluteJoint "robotiq_85_left_finger_tip_joint" (
            prepend apiSchemas = ["NewtonMimicAPI", "PhysicsDriveAPI:angular", "PhysicsJointStateAPI:angular"]
        )
        {
            float newton:mimicCoef1 = -1
            rel newton:mimicJoint = </robotiq_gripper/Physics/robotiq_85_left_knuckle_joint>
            uniform token physics:axis = "Y"
            custom rel physics:body0
            prepend rel physics:body0 = </robotiq_gripper>
            custom rel physics:body1
            prepend rel physics:body1 = </robotiq_gripper/Geometry/world/robotiq_85_base_link/robotiq_85_left_knuckle_link/robotiq_85_left_finger_link/robotiq_85_left_finger_tip_link>
            point3f physics:localPos0 = (0.06775864, 0, 0.0983262)
            point3f physics:localPos1 = (0, 0, 0)
            quatf physics:localRot0 = (0, -1, 0, 0)
            quatf physics:localRot1 = (0, -1, 0, 0)
        }

        def PhysicsRevoluteJoint "robotiq_85_right_finger_tip_joint" (
            prepend apiSchemas = ["NewtonMimicAPI", "PhysicsDriveAPI:angular", "PhysicsJointStateAPI:angular"]
        )
        {
            rel newton:mimicJoint = </robotiq_gripper/Physics/robotiq_85_left_knuckle_joint>
            uniform token physics:axis = "Y"
            custom rel physics:body0
            prepend rel physics:body0 = </robotiq_gripper>
            custom rel physics:body1
            prepend rel physics:body1 = </robotiq_gripper/Geometry/world/robotiq_85_base_link/robotiq_85_right_knuckle_link/robotiq_85_right_finger_link/robotiq_85_right_finger_tip_link>
            point3f physics:localPos0 = (-0.06775864, 0, 0.0983262)
            point3f physics:localPos1 = (0, 0, 0)
            quatf physics:localRot0 = (0, -1, 0, 0)
            quatf physics:localRot1 = (0, -1, 0, 0)
        }

        def PhysicsFixedJoint "robotiq_85_base_joint"
        {
            custom rel physics:body0
            prepend rel physics:body0 = </robotiq_gripper>
            custom rel physics:body1
            prepend rel physics:body1 = </robotiq_gripper/Geometry/world/robotiq_85_base_link>
            point3f physics:localPos0 = (0, 0, 0)
            point3f physics:localPos1 = (0, 0, 0)
            quatf physics:localRot0 = (1, 0, 0, 0)
            quatf physics:localRot1 = (1, 0, 0, 0)
        }

        def PhysicsFixedJoint "robotiq_85_left_finger_joint"
        {
            custom rel physics:body0
            prepend rel physics:body0 = </robotiq_gripper>
            custom rel physics:body1
            prepend rel physics:body1 = </robotiq_gripper/Geometry/world/robotiq_85_base_link/robotiq_85_left_knuckle_link/robotiq_85_left_finger_link>
            point3f physics:localPos0 = (0.0621273, 0, 0.05114105)
            point3f physics:localPos1 = (0, 0, 0)
            quatf physics:localRot0 = (1, 0, 0, 0)
            quatf physics:localRot1 = (1, 0, 0, 0)
        }

        def PhysicsFixedJoint "robotiq_85_right_finger_joint"
        {
            custom rel physics:body0
            prepend rel physics:body0 = </robotiq_gripper>
            custom rel physics:body1
            prepend rel physics:body1 = </robotiq_gripper/Geometry/world/robotiq_85_base_link/robotiq_85_right_knuckle_link/robotiq_85_right_finger_link>
            point3f physics:localPos0 = (-0.0621273, 0, 0.05114105)
            point3f physics:localPos1 = (0, 0, 0)
            quatf physics:localRot0 = (1, 0, 0, 0)
            quatf physics:localRot1 = (1, 0, 0, 0)
        }
    }
}

