#usda 1.0
(
    customLayerData = {
        string creator = "URDF USD Converter v0.1.0"
    }
    defaultPrim = "ur5e"
    doc = """Generated from Composed Stage of root layer /tmp/tmp74qddely/ur5e.usdc


Generated from Composed Stage of root layer /workspace/assets/ur5e.usd/usdex/ur5e.usdc


Generated from Composed Stage of root layer /workspace/assets/ur5e.usd/temp/ur5e.usd


Generated from Composed Stage of root layer /workspace/assets/ur5e.usd/ur5e/payloads/base.usd
"""
    kilogramsPerUnit = 1
    metersPerUnit = 1
    upAxis = "Z"
)

over "ur5e"
{
    over "Geometry"
    {
        over "world"
        {
            over "base_link" (
                prepend apiSchemas = ["PhysicsRigidBodyAPI", "PhysicsArticulationRootAPI", "NewtonArticulationRootAPI", "PhysicsMassAPI"]
            )
            {
                bool newton:selfCollisionEnabled = 0

                over "base_link_inertia" (
                    prepend apiSchemas = ["PhysicsRigidBodyAPI", "PhysicsMassAPI"]
                )
                {
                    point3f physics:centerOfMass = (0, 0, 0)
                    float3 physics:diagonalInertia = (0.0044333315, 0.0044333315, 0.0072)
                    float physics:mass = 4
                    quatf physics:principalAxes = (1, 0, 0, 0)

                    over "shoulder_link" (
                        prepend apiSchemas = ["PhysicsRigidBodyAPI", "PhysicsMassAPI"]
                    )
                    {
                        point3f physics:centerOfMass = (0, -0.00193, -0.02561)
                        float3 physics:diagonalInertia = (0.006024776, 0.0070003048, 0.0070307893)
                        float physics:mass = 3.761
                        quatf physics:principalAxes = (-0.67473114, 0.20206705, 0.60877776, 0.36509764)

                        over "upper_arm_link" (
                            prepend apiSchemas = ["PhysicsRigidBodyAPI", "PhysicsMassAPI"]
                        )
                        {
                            point3f physics:centerOfMass = (-0.2125, 0, 0.11336)
                            float3 physics:diagonalInertia = (0.015058841, 0.33247206, 0.33388087)
                            float physics:mass = 8.058
                            quatf physics:principalAxes = (0.70756114, -0.70665216, -0.000066118744, -0.000053654363)

                            over "forearm_link" (
                                prepend apiSchemas = ["PhysicsRigidBodyAPI", "PhysicsMassAPI"]
                            )
                            {
                                point3f physics:centerOfMass = (-0.2422, 0, 0.0265)
                                float3 physics:diagonalInertia = (0.003971029, 0.078510225, 0.078792706)
                                float physics:mass = 2.846
                                quatf physics:principalAxes = (0.71560067, -0.6984489, -0.006654075, 0.0063682753)

                                over "wrist_1_link" (
                                    prepend apiSchemas = ["PhysicsRigidBodyAPI", "PhysicsMassAPI"]
                                )
                                {
                                    point3f physics:centerOfMass = (0, -0.01634, -0.0018)
                                    float3 physics:diagonalInertia = (0.0011986756, 0.0014236274, 0.001655017)
                                    float physics:mass = 1.37
                                    quatf physics:principalAxes = (0.61716497, 0.34859392, 0.33430785, 0.6211505)

                                    over "wrist_2_link" (
                                        prepend apiSchemas = ["PhysicsRigidBodyAPI", "PhysicsMassAPI"]
                                    )
                                    {
                                        point3f physics:centerOfMass = (0, 0.01634, -0.0018)
                                        float3 physics:diagonalInertia = (0.00095813966, 0.0012860664, 0.001356374)
                                        float physics:mass = 1.3
                                        quatf physics:principalAxes = (0.5457389, -0.4440672, 0.47465158, -0.5288471)

                                        over "wrist_3_link" (
                                            prepend apiSchemas = ["PhysicsRigidBodyAPI", "PhysicsMassAPI"]
                                        )
                                        {
                                            point3f physics:centerOfMass = (0, 0, -0.001159)
                                            float3 physics:diagonalInertia = (0.00018693802, 0.00018906921, 0.00025757277)
                                            float physics:mass = 0.365
                                            quatf physics:principalAxes = (0.99988484, -0.0067323972, 0.0011178805, 0.013553714)

                                            over "ft_frame" (
                                                prepend apiSchemas = ["PhysicsRigidBodyAPI", "PhysicsMassAPI"]
                                            )
                                            {
                                            }

                                            over "flange" (
                                                prepend apiSchemas = ["PhysicsRigidBodyAPI", "PhysicsMassAPI"]
                                            )
                                            {
                                                over "tool0" (
                                                    prepend apiSchemas = ["PhysicsRigidBodyAPI", "PhysicsMassAPI"]
                                                )
                                                {
                                                }
                                            }
                                        }
                                    }
                                }
                            }
                        }
                    }
                }

                over "base" (
                    prepend apiSchemas = ["PhysicsRigidBodyAPI", "PhysicsMassAPI"]
                )
                {
                }
            }
        }
    }

    over "Physics"
    {
        def PhysicsRevoluteJoint "shoulder_pan_joint" (
            prepend apiSchemas = ["PhysicsDriveAPI:angular", "PhysicsJointStateAPI:angular"]
        )
        {
            float drive:angular:physics:maxForce = 150
            uniform token physics:axis = "Z"
            custom rel physics:body0
            prepend rel physics:body0 = </ur5e>
            custom rel physics:body1
            prepend rel physics:body1 = </ur5e/Geometry/world/base_link/base_link_inertia/shoulder_link>
            point3f physics:localPos0 = (0, 0, 0.1625)
            point3f physics:localPos1 = (0, 0, 0)
            quatf physics:localRot0 = (6.123234e-17, 0, 0, 1)
            quatf physics:localRot1 = (1, 0, 0, 0)
            float physics:lowerLimit = -360
            float physics:upperLimit = 360
            custom float urdf:dynamics:damping = 0
            custom float urdf:dynamics:friction = 0
            custom float urdf:limit:effort = 150
            custom float urdf:limit:velocity = 3.1415927
        }

        def PhysicsRevoluteJoint "shoulder_lift_joint" (
            prepend apiSchemas = ["PhysicsDriveAPI:angular", "PhysicsJointStateAPI:angular"]
        )
        {
            float drive:angular:physics:maxForce = 150
            uniform token physics:axis = "Z"
            custom rel physics:body0
            prepend rel physics:body0 = </ur5e>
            custom rel physics:body1
            prepend rel physics:body1 = </ur5e/Geometry/world/base_link/base_link_inertia/shoulder_link/upper_arm_link>
            point3f physics:localPos0 = (0, 0, 0.1625)
            point3f physics:localPos1 = (0, 0, 0)
            quatf physics:localRot0 = (6.123234e-17, 4.3297803e-17, 0.70710677, 0.70710677)
            quatf physics:localRot1 = (1, 0, 0, 0)
            float physics:lowerLimit = -360
            float physics:upperLimit = 360
            custom float urdf:dynamics:damping = 0
            custom float urdf:dynamics:friction = 0
            custom float urdf:limit:effort = 150
            custom float urdf:limit:velocity = 3.1415927
        }

        def PhysicsRevoluteJoint "elbow_joint" (
            prepend apiSchemas = ["PhysicsDriveAPI:angular", "PhysicsJointStateAPI:angular"]
        )
        {
            float drive:angular:physics:maxForce = 150
            uniform token physics:axis = "Z"
            custom rel physics:body0
            prepend rel physics:body0 = </ur5e>
            custom rel physics:body1
            prepend rel physics:body1 = </ur5e/Geometry/world/base_link/base_link_inertia/shoulder_link/upper_arm_link/forearm_link>
            point3f physics:localPos0 = (0.425, -5.2047488e-17, 0.1625)
            point3f physics:localPos1 = (0, 0, 0)
            quatf physics:localRot0 = (6.123234e-17, 4.3297803e-17, 0.70710677, 0.70710677)
            quatf physics:localRot1 = (1, 0, 0, 0)
            float physics:lowerLimit = -180
            float physics:upperLimit = 180
            custom float urdf:dynamics:damping = 0
            custom float urdf:dynamics:friction = 0
            custom float urdf:limit:effort = 150
            custom float urdf:limit:velocity = 3.1415927
        }

        def PhysicsRevoluteJoint "wrist_1_joint" (
            prepend apiSchemas = ["PhysicsDriveAPI:angular", "PhysicsJointStateAPI:angular"]
        )
        {
            float drive:angular:physics:maxForce = 28
            uniform token physics:axis = "Z"
            custom rel physics:body0
            prepend rel physics:body0 = </ur5e>
            custom rel physics:body1
            prepend rel physics:body1 = </ur5e/Geometry/world/base_link/base_link_inertia/shoulder_link/upper_arm_link/forearm_link/wrist_1_link>
            point3f physics:localPos0 = (0.8172, 0.1333, 0.1625)
            point3f physics:localPos1 = (0, 0, 0)
            quatf physics:localRot0 = (6.123234e-17, 4.3297803e-17, 0.70710677, 0.70710677)
            quatf physics:localRot1 = (1, 0, 0, 0)
            float physics:lowerLimit = -360
            float physics:upperLimit = 360
            custom float urdf:dynamics:damping = 0
            custom float urdf:dynamics:friction = 0
            custom float urdf:limit:effort = 28
            custom float urdf:limit:velocity = 3.1415927
        }

        def PhysicsRevoluteJoint "wrist_2_joint" (
            prepend apiSchemas = ["PhysicsDriveAPI:angular", "PhysicsJointStateAPI:angular"]
        )
        {
            float drive:angular:physics:maxForce = 28
            uniform token physics:axis = "Z"
            custom rel physics:body0
            prepend rel physics:body0 = </ur5e>
            custom rel physics:body1
            prepend rel physics:body1 = </ur5e/Geometry/world/base_link/base_link_inertia/shoulder_link/upper_arm_link/forearm_link/wrist_1_link/wrist_2_link>
            point3f physics:localPos0 = (0.8172, 0.13329999, 0.0628)
            point3f physics:localPos1 = (0, 0, 0)
            quatf physics:localRot0 = (6.123234e-17, 6.123234e-17, 1, -3.4228542e-8)
            quatf physics:localRot1 = (1, 0, 0, 0)
            float physics:lowerLimit = -360
            float physics:upperLimit = 360
            custom float urdf:dynamics:damping = 0
            custom float urdf:dynamics:friction = 0
            custom float urdf:limit:effort = 28
            custom float urdf:limit:velocity = 3.1415927
        }

        def PhysicsRevoluteJoint "wrist_3_joint" (
            prepend apiSchemas = ["PhysicsDriveAPI:angular", "PhysicsJointStateAPI:angular"]
        )
        {
            float drive:angular:physics:maxForce = 28
            uniform token physics:axis = "Z"
            custom rel physics:body0
            prepend rel physics:body0 = </ur5e>
            custom rel physics:body1
            prepend rel physics:body1 = </ur5e/Geometry/world/base_link/base_link_inertia/shoulder_link/upper_arm_link/forearm_link/wrist_1_link/wrist_2_link/wrist_3_link>
            point3f physics:localPos0 = (0.8172, 0.2329, 0.06279999)
            point3f physics:localPos1 = (0, 0, 0)
            quatf physics:localRot0 = (6.123234e-17, 6.123234e-17, 0.70710677, 0.70710677)
            quatf physics:localRot1 = (1, 0, 0, 0)
            float physics:lowerLimit = -360
            float physics:upperLimit = 360
            custom float urdf:dynamics:damping = 0
            custom float urdf:dynamics:friction = 0
            custom float urdf:limit:effort = 28
            custom float urdf:limit:velocity = 3.1415927
        }

        def PhysicsFixedJoint "base_joint"
        {
            custom rel physics:body0
            prepend rel physics:body0 = </ur5e>
            custom rel physics:body1
            prepend rel physics:body1 = </ur5e/Geometry/world/base_link>
            point3f physics:localPos0 = (0, 0, 0)
            point3f physics:localPos1 = (0, 0, 0)
            quatf physics:localRot0 = (1, 0, 0, 0)
            quatf physics:localRot1 = (1, 0, 0, 0)
        }

        def PhysicsFixedJoint "tn__base_linkbase_link_inertia_kc0"
        {
            custom rel physics:body0
            prepend rel physics:body0 = </ur5e>
            custom rel physics:body1
            prepend rel physics:body1 = </ur5e/Geometry/world/base_link/base_link_inertia>
            point3f physics:localPos0 = (0, 0, 0)
            point3f physics:localPos1 = (0, 0, 0)
            quatf physics:localRot0 = (6.123234e-17, 0, 0, 1)
            quatf physics:localRot1 = (1, 0, 0, 0)
        }

        def PhysicsFixedJoint "tn__wrist_3_linkft_frame_wT"
        {
            custom rel physics:body0
            prepend rel physics:body0 = </ur5e>
            custom rel physics:body1
            prepend rel physics:body1 = </ur5e/Geometry/world/base_link/base_link_inertia/shoulder_link/upper_arm_link/forearm_link/wrist_1_link/wrist_2_link/wrist_3_link/ft_frame>
            point3f physics:localPos0 = (0.8172, 0.2329, 0.06279999)
            point3f physics:localPos1 = (0, 0, 0)
            quatf physics:localRot0 = (6.123234e-17, 4.3297806e-17, -0.70710677, 0.70710677)
            quatf physics:localRot1 = (1, 0, 0, 0)
        }

        def PhysicsFixedJoint "tn__base_linkbase_fixed_joint_Wb0"
        {
            custom rel physics:body0
            prepend rel physics:body0 = </ur5e>
            custom rel physics:body1
            prepend rel physics:body1 = </ur5e/Geometry/world/base_link/base>
            point3f physics:localPos0 = (0, 0, 0)
            point3f physics:localPos1 = (0, 0, 0)
            quatf physics:localRot0 = (6.123234e-17, 0, 0, 1)
            quatf physics:localRot1 = (1, 0, 0, 0)
        }

        def PhysicsFixedJoint "tn__wrist_3flange_mJ"
        {
            custom rel physics:body0
            prepend rel physics:body0 = </ur5e>
            custom rel physics:body1
            prepend rel physics:body1 = </ur5e/Geometry/world/base_link/base_link_inertia/shoulder_link/upper_arm_link/forearm_link/wrist_1_link/wrist_2_link/wrist_3_link/flange>
            point3f physics:localPos0 = (0.8172, 0.2329, 0.06279999)
            point3f physics:localPos1 = (0, 0, 0)
            quatf physics:localRot0 = (0.70710677, -1.2101617e-8, 1.2101617e-8, 0.70710677)
            quatf physics:localRot1 = (1, 0, 0, 0)
        }

        def PhysicsFixedJoint "tn__flangetool0_oG"
        {
            custom rel physics:body0
            prepend rel physics:body0 = </ur5e>
            custom rel physics:body1
            prepend rel physics:body1 = </ur5e/Geometry/world/base_link/base_link_inertia/shoulder_link/upper_arm_link/forearm_link/wrist_1_link/wrist_2_link/wrist_3_link/flange/tool0>
            point3f physics:localPos0 = (0.8172, 0.2329, 0.06279999)
            point3f physics:localPos1 = (0, 0, 0)
            quatf physics:localRot0 = (-3.8285688e-16, 1.1213769e-16, 0.70710677, 0.70710677)
            quatf physics:localRot1 = (1, 0, 0, 0)
        }
    }
}

